<?xml version='1.0'?>
<sdf version='1.6'>
  <model name='cessna_naca'>
    <link name='link_6'>
<pose>-0.7 0 1.5 1.5708 0 3.1415</pose>
      <inertial>
        <mass>1</mass>
        <inertia>
          <ixx>0.166667</ixx>
          <ixy>0</ixy>
          <ixz>0</ixz>
          <iyy>0.166667</iyy>
          <iyz>0</iyz>
          <izz>0.166667</izz>
        </inertia>
        <pose frame=''>0 0 0 0 -0 0</pose>
      </inertial>
      <pose frame=''>1.91746 -5.95727 2.29132 1.55593 -0.008316 -3.13996</pose>
      <gravity>1</gravity>
      <self_collide>0</self_collide>
      <kinematic>0</kinematic>
      <enable_wind>0</enable_wind>
      <visual name='visual'>
        <pose frame=''>0 0 0 0 -0 0</pose>
        <geometry>
          <mesh>
            <uri>model://cessna/meshes/naca0015.dae</uri>
            <scale>10 10 20</scale>
          </mesh>
        </geometry>
        <material>
            <lighting>1</lighting>
            <script>
              <uri>file://media/materials/scripts/gazebo.material</uri>
              <name>Gazebo/Grey</name>
            </script>
          </material>
          <transparency>0</transparency>
          <cast_shadows>1</cast_shadows>
        <transparency>0</transparency>
        <cast_shadows>1</cast_shadows>
      </visual>
      <collision name='collision'>
        <laser_retro>0</laser_retro>
        <max_contacts>10</max_contacts>
        <pose frame=''>0 0 0 0 -0 0</pose>
        <geometry>
          <mesh>
            <uri>model://cessna/meshes/naca0015.dae</uri>
            <scale>1 1 1</scale>
          </mesh>
        </geometry>
        <surface>
          <friction>
            <ode>
              <mu>1</mu>
              <mu2>1</mu2>
              <fdir1>0 0 0</fdir1>
              <slip1>0</slip1>
              <slip2>0</slip2>
            </ode>
            <torsional>
              <coefficient>1</coefficient>
              <patch_radius>0</patch_radius>
              <surface_radius>0</surface_radius>
              <use_patch_radius>1</use_patch_radius>
              <ode>
                <slip>0</slip>
              </ode>
            </torsional>
          </friction>
          <bounce>
            <restitution_coefficient>0</restitution_coefficient>
            <threshold>1e+06</threshold>
          </bounce>
          <contact>
            <collide_without_contact>0</collide_without_contact>
            <collide_without_contact_bitmask>1</collide_without_contact_bitmask>
            <collide_bitmask>1</collide_bitmask>
            <ode>
              <soft_cfm>0</soft_cfm>
              <soft_erp>0.2</soft_erp>
              <kp>1e+13</kp>
              <kd>1</kd>
              <max_vel>0.01</max_vel>
              <min_depth>0</min_depth>
            </ode>
            <bullet>
              <split_impulse>1</split_impulse>
              <split_impulse_penetration_threshold>-0.01</split_impulse_penetration_threshold>
              <soft_cfm>0</soft_cfm>
              <soft_erp>0.2</soft_erp>
              <kp>1e+13</kp>
              <kd>1</kd>
            </bullet>
          </contact>
        </surface>
      </collision>
    </link>
    <link name='link_6_clone'>
<pose>-0.7 0 1.5 -1.5708 0 3.1415</pose>
      <inertial>
        <mass>1</mass>
        <inertia>
          <ixx>0.166667</ixx>
          <ixy>0</ixy>
          <ixz>0</ixz>
          <iyy>0.166667</iyy>
          <iyz>0</iyz>
          <izz>0.166667</izz>
        </inertia>
        <pose frame=''>0 0 0 0 -0 0</pose>
      </inertial>
      <pose frame=''>1.92491 -2.97869 2.33322 1.55593 -0.008316 -3.13996</pose>
      <gravity>1</gravity>
      <self_collide>0</self_collide>
      <kinematic>0</kinematic>
      <enable_wind>0</enable_wind>
      <visual name='visual'>
        <pose frame=''>0 0 0 0 -0 0</pose>
        <geometry>
          <mesh>
            <uri>model://cessna/meshes/naca0015.dae</uri>
            <scale>10 10 20</scale>
          </mesh>
        </geometry>
        <material>
            <lighting>1</lighting>
            <script>
              <uri>file://media/materials/scripts/gazebo.material</uri>
              <name>Gazebo/Grey</name>
            </script>
          </material>
          <transparency>0</transparency>
          <cast_shadows>1</cast_shadows>
        <transparency>0</transparency>
        <cast_shadows>1</cast_shadows>
      </visual>
      <collision name='collision'>
        <laser_retro>0</laser_retro>
        <max_contacts>10</max_contacts>
        <pose frame=''>0 0 0 0 -0 0</pose>
        <geometry>
          <mesh>
            <uri>model://cessna/meshes/naca0015.dae</uri>
            <scale>1 1 1</scale>
          </mesh>
        </geometry>
        <surface>
          <friction>
            <ode>
              <mu>1</mu>
              <mu2>1</mu2>
              <fdir1>0 0 0</fdir1>
              <slip1>0</slip1>
              <slip2>0</slip2>
            </ode>
            <torsional>
              <coefficient>1</coefficient>
              <patch_radius>0</patch_radius>
              <surface_radius>0</surface_radius>
              <use_patch_radius>1</use_patch_radius>
              <ode>
                <slip>0</slip>
              </ode>
            </torsional>
          </friction>
          <bounce>
            <restitution_coefficient>0</restitution_coefficient>
            <threshold>1e+06</threshold>
          </bounce>
          <contact>
            <collide_without_contact>0</collide_without_contact>
            <collide_without_contact_bitmask>1</collide_without_contact_bitmask>
            <collide_bitmask>1</collide_bitmask>
            <ode>
              <soft_cfm>0</soft_cfm>
              <soft_erp>0.2</soft_erp>
              <kp>1e+13</kp>
              <kd>1</kd>
              <max_vel>0.01</max_vel>
              <min_depth>0</min_depth>
            </ode>
            <bullet>
              <split_impulse>1</split_impulse>
              <split_impulse_penetration_threshold>-0.01</split_impulse_penetration_threshold>
              <soft_cfm>0</soft_cfm>
              <soft_erp>0.2</soft_erp>
              <kp>1e+13</kp>
              <kd>1</kd>
            </bullet>
          </contact>
        </surface>
      </collision>
    </link>
      <link name='body'>
        <inertial>
          <mass>1</mass>
          <inertia>
          <ixx>1285.315427874</ixx>
          <ixy>0.0</ixy>
          <iyy>1824.930976707</iyy>
          <ixz>0.0</ixz>
          <iyz>0.0</iyz>
          <izz>2666.893931043</izz>
        </inertia>
        </inertial>
        <pose frame=''>0 0 0 1.58268 0 0</pose>
        <visual name='visual'>
          <pose frame=''>0 0 0 0 0 0</pose>
          <geometry>
            <mesh>
              <uri>model://cessna/meshes/body-no-wing.dae</uri>
              <scale>1 1 1</scale>
            </mesh>
          </geometry>
          <material>
            <lighting>1</lighting>
            <script>
              <uri>file://media/materials/scripts/gazebo.material</uri>
              <name>Gazebo/Grey</name>
            </script>
          </material>
          <transparency>0</transparency>
          <cast_shadows>1</cast_shadows>
        </visual>
        <collision name='collision'>
          <laser_retro>0</laser_retro>
          <max_contacts>10</max_contacts>
          <pose frame=''>0 0 0 0 -0 0</pose>
          <geometry>
            <mesh>
              <uri>model://cessna/meshes/body-no-wing.dae</uri>
              <scale>1 1 1</scale>
            </mesh>
          </geometry>
          <surface>
            <friction>
              <ode>
                <mu>1</mu>
                <mu2>1</mu2>
                <fdir1>0 0 0</fdir1>
                <slip1>0</slip1>
                <slip2>0</slip2>
              </ode>
              <torsional>
                <coefficient>1</coefficient>
                <patch_radius>0</patch_radius>
                <surface_radius>0</surface_radius>
                <use_patch_radius>1</use_patch_radius>
                <ode>
                  <slip>0</slip>
                </ode>
              </torsional>
            </friction>
            <bounce>
              <restitution_coefficient>0</restitution_coefficient>
              <threshold>1e+06</threshold>
            </bounce>
            <contact>
              <collide_without_contact>0</collide_without_contact>
              <collide_without_contact_bitmask>1</collide_without_contact_bitmask>
              <collide_bitmask>1</collide_bitmask>
              <ode>
                <soft_cfm>0</soft_cfm>
                <soft_erp>0.2</soft_erp>
                <kp>1e+13</kp>
                <kd>1</kd>
                <max_vel>0.01</max_vel>
                <min_depth>0</min_depth>
              </ode>
              <bullet>
                <split_impulse>1</split_impulse>
                <split_impulse_penetration_threshold>-0.01</split_impulse_penetration_threshold>
                <soft_cfm>0</soft_cfm>
                <soft_erp>0.2</soft_erp>
                <kp>1e+13</kp>
                <kd>1</kd>
              </bullet>
            </contact>
          </surface>
        </collision>
      </link>
      <static>0</static>
      <allow_auto_disable>1</allow_auto_disable>
      <pose frame=''>2.3939 -3.41614 0.811487 0 -0 0</pose>
    <static>0</static>
    <allow_auto_disable>1</allow_auto_disable>

<link name="left_aileron">
      <inertial>
        <mass>2</mass>
        <inertia>
          <ixx>0.8434</ixx>
          <ixy>0.0</ixy>
          <iyy>0.0119</iyy>
          <ixz>0.0</ixz>
          <iyz>0.0</iyz>
          <izz>0.855</izz>
        </inertia>
        <pose>-1.65 3.7 1.5 0.05 0 -0.12</pose>
      </inertial>

      <collision name="collision">
        <geometry>
          <mesh>
            <uri>model://cessna/meshes/left_aileron.dae</uri>
          </mesh>
        </geometry>
      </collision>

     <!-- <visual name="visual">
        <geometry>
          <mesh>
            <uri>model://cessna/meshes/left_aileron.dae</uri>
          </mesh>
        </geometry>
      </visual>-->
    </link>

    <link name="left_flap">
      <inertial>
        <mass>2</mass>
        <inertia>
          <ixx>0.6747</ixx>
          <ixy>0.0</ixy>
          <iyy>0.0242</iyy>
          <ixz>0.0</ixz>
          <iyz>0.0</iyz>
          <izz>0.6962</izz>
        </inertia>
        <pose>-1.8 1.55 1.43 0.02 0 0</pose>
      </inertial>

      <collision name="collision">
        <geometry>
          <mesh>
            <uri>model://cessna/meshes/left_flap.dae</uri>
          </mesh>
        </geometry>
      </collision>

     <!-- <visual name="visual">
        <geometry>
          <mesh>
            <uri>model://cessna/meshes/left_flap.dae</uri>
          </mesh>
        </geometry>
      </visual>-->
    </link>

    <link name="right_aileron">
      <inertial>
        <mass>2</mass>
        <inertia>
          <ixx>0.8434</ixx>
          <ixy>0.0</ixy>
          <iyy>0.0119</iyy>
          <ixz>0.0</ixz>
          <iyz>0.0</iyz>
          <izz>0.855</izz>
        </inertia>
        <pose>-1.65 -3.7 1.5 -0.05 0 0.12</pose>
      </inertial>

      <collision name="collision">
        <geometry>
          <mesh>
            <uri>model://cessna/meshes/right_aileron.dae</uri>
          </mesh>
        </geometry>
      </collision>

     <!-- <visual name="visual">
        <geometry>
          <mesh>
            <uri>model://cessna/meshes/right_aileron.dae</uri>
          </mesh>
        </geometry>
      </visual>-->
    </link>

    <link name="right_flap">
      <inertial>
        <mass>2</mass>
        <inertia>
          <ixx>0.6747</ixx>
          <ixy>0.0</ixy>
          <iyy>0.0242</iyy>
          <ixz>0.0</ixz>
          <iyz>0.0</iyz>
          <izz>0.6962</izz>
        </inertia>
        <pose>-1.8 -1.55 1.43 -0.02 0 0</pose>
      </inertial>

      <collision name="collision">
        <geometry>
          <mesh>
            <uri>model://cessna/meshes/right_flap.dae</uri>
          </mesh>
        </geometry>
      </collision>

     <!-- <visual name="visual">
        <geometry>
          <mesh>
            <uri>model://cessna/meshes/right_flap.dae</uri>
          </mesh>
        </geometry>
      </visual>-->
    </link>

    <link name="elevators">
      <inertial>
        <mass>2</mass>
        <inertia>
          <ixx>1.5008</ixx>
          <ixy>0.0</ixy>
          <iyy>0.0274</iyy>
          <ixz>0.0</ixz>
          <iyz>0.0</iyz>
          <izz>1.5266</izz>
        </inertia>
        <pose>-5.75 0 0.57 0 0 0</pose>
      </inertial>

      <collision name="collision">
        <geometry>
          <mesh>
            <uri>model://cessna/meshes/elevators.dae</uri>
          </mesh>
        </geometry>
      </collision>

      <visual name="visual">
        <geometry>
          <mesh>
            <uri>model://cessna/meshes/elevators.dae</uri>
          </mesh>
        </geometry>
      </visual>
    </link>

    <link name="rudder">
      <inertial>
        <mass>2</mass>
        <inertia>
          <ixx>0.4708</ixx>
          <ixy>0.0</ixy>
          <iyy>0.5208</iyy>
          <ixz>0.0</ixz>
          <iyz>0.0</iyz>
          <izz>0.0508</izz>
        </inertia>
        <pose>-6.1 0 1.3 0 -0.35 0</pose>
      </inertial>

      <collision name="collision">
        <geometry>
          <mesh>
            <uri>model://cessna/meshes/rudder.dae</uri>
          </mesh>
        </geometry>
      </collision>

      <visual name="visual">
        <geometry>
          <mesh>
            <uri>model://cessna/meshes/rudder.dae</uri>
          </mesh>
        </geometry>
      </visual>
    </link>

    <link name="propeller">
      <pose>1.79 0 0.855 0 0 0</pose>
      <inertial>
        <mass>18.37</mass>
        <inertia>
          <ixx>7.5067</ixx>
          <ixy>0</ixy>
          <iyy>7.5150</iyy>
          <ixz>0</ixz>
          <iyz>0</iyz>
          <izz>0.068275</izz>
        </inertia>
        <pose>-0.35 0 0 0 0 0</pose>
      </inertial>

      <collision name="collision">
        <geometry>
          <!-- In case a simple shape is preferred -->
          <!--box><size>0.05 0.14 2.21</size></box>-->
          <mesh>
            <uri>model://cessna/meshes/cessna_prop.dae</uri>
          </mesh>
        </geometry>
      </collision>
     <!-- <visual name="visual">
        <geometry>
          <mesh>
            <uri>model://cessna/meshes/cessna_prop.dae</uri>
          </mesh>
        </geometry>
      </visual>-->
    </link>

    <link name="front_wheel">
      <inertial>
        <mass>2</mass>
        <inertia>
          <ixx>0.01786</ixx>
          <ixy>0</ixy>
          <iyy>0.01786</iyy>
          <ixz>0</ixz>
          <iyz>0</iyz>
          <izz>0.0324</izz>
        </inertia>
        <pose>0.712 0 -0.313 1.570795 0 0</pose>
      </inertial>
      <collision name="collision">
        <pose>0.712 0 -0.313 1.570795 0 0</pose>
        <geometry>
          <cylinder>
              <radius>0.18</radius>
              <length>0.1</length>
          </cylinder>
        </geometry>
        <surface>
          <friction>
            <ode>
              <mu>0.3</mu>
              <mu2>0.3</mu2>
            </ode>
          </friction>
          <contact>
            <ode>
              <max_vel>0.1</max_vel>
              <min_depth>0.001</min_depth>
            </ode>
          </contact>
        </surface>
      </collision>

      <visual name="visual">
        <geometry>
          <mesh>
            <uri>model://cessna/meshes/cessna_front_wheel.dae</uri>
          </mesh>
        </geometry>
      </visual>
    </link>

    <link name="rear_left_wheel">
      <inertial>
        <mass>2</mass>
        <inertia>
          <ixx>0.035516</ixx>
          <ixy>0</ixy>
          <iyy>0.035516</iyy>
          <ixz>0</ixz>
          <iyz>0</iyz>
          <izz>0.0625</izz>
        </inertia>
        <pose>-1 1.27 -0.25 1.570795 0 0</pose>
      </inertial>
      <collision name="collision">
        <pose>-1 1.27 -0.25 1.570795 0 0</pose>
        <geometry>
          <cylinder>
              <radius>0.25</radius>
              <length>0.16</length>
          </cylinder>
        </geometry>
        <surface>
          <friction>
            <ode>
              <mu>0.3</mu>
              <mu2>0.3</mu2>
            </ode>
          </friction>
          <contact>
            <ode>
              <max_vel>0.1</max_vel>
              <min_depth>0.001</min_depth>
            </ode>
          </contact>
        </surface>
      </collision>

      <visual name="visual">
        <geometry>
          <mesh>
            <uri>model://cessna/meshes/cessna_rear_left_wheel.dae</uri>
          </mesh>
        </geometry>
      </visual>
    </link>

    <link name="rear_right_wheel">
      <inertial>
        <mass>2</mass>
        <inertia>
          <ixx>0.035516</ixx>
          <ixy>0</ixy>
          <iyy>0.035516</iyy>
          <ixz>0</ixz>
          <iyz>0</iyz>
          <izz>0.0625</izz>
        </inertia>
        <pose>-1 -1.27 -0.25 1.570795 0 0</pose>
      </inertial>
      <collision name="collision">
        <pose>-1 -1.27 -0.25 1.570795 0 0</pose>
        <geometry>
          <cylinder>
              <radius>0.25</radius>
              <length>0.16</length>
          </cylinder>
        </geometry>
        <surface>
          <friction>
            <ode>
              <mu>0.3</mu>
              <mu2>0.3</mu2>
            </ode>
          </friction>
          <contact>
            <ode>
              <max_vel>0.1</max_vel>
              <min_depth>0.001</min_depth>
            </ode>
          </contact>
        </surface>
      </collision>

      <visual name="visual">
        <geometry>
          <mesh>
            <uri>model://cessna/meshes/cessna_rear_right_wheel.dae</uri>
          </mesh>
        </geometry>
      </visual>
    </link>

    <!-- Joint to move the left flap -->
    <joint name='left_flap_joint' type='revolute'>
      <parent>body</parent>
      <child>left_flap</child>
      <pose>-1.6 1.55 1.43 0.02 0 0</pose>
      <axis>
        <xyz>0 1 0</xyz>
        <limit>
          <!-- -30/+30 deg. -->
          <lower>-0.53</lower>
          <upper>0.53</upper>
          <effort>-1</effort>
          <velocity>-1</velocity>
        </limit>
        <dynamics>
          <damping>1.000</damping>
        </dynamics>
      </axis>
      <physics>
        <ode>
          <implicit_spring_damper>1</implicit_spring_damper>
        </ode>
      </physics>
    </joint>

    <!-- Joint to move the left aileron -->
    <joint name='left_aileron_joint' type='revolute'>
      <parent>body</parent>
      <child>left_aileron</child>
      <pose>-1.45 3.7 1.5 0.05 0 -0.12</pose>
      <axis>
        <xyz>0 1 0</xyz>
        <limit>
          <!-- -30/+30 deg. -->
          <lower>-0.53</lower>
          <upper>0.53</upper>
          <effort>-1</effort>
          <velocity>-1</velocity>
        </limit>
        <dynamics>
          <damping>1.000</damping>
        </dynamics>
      </axis>
      <physics>
        <ode>
          <implicit_spring_damper>1</implicit_spring_damper>
        </ode>
      </physics>
    </joint>

    <!-- Joint to move the right flap -->
    <joint name='right_flap_joint' type='revolute'>
      <parent>body</parent>
      <child>right_flap</child>
      <pose>-1.6 -1.55 1.43 -0.02 0 0</pose>
      <axis>
        <xyz>0 1 0</xyz>
        <limit>
          <!-- -30/+30 deg. -->
          <lower>-0.53</lower>
          <upper>0.53</upper>
          <effort>-1</effort>
          <velocity>-1</velocity>
        </limit>
        <dynamics>
          <damping>1.000</damping>
        </dynamics>
      </axis>
      <physics>
        <ode>
          <implicit_spring_damper>1</implicit_spring_damper>
        </ode>
      </physics>
    </joint>

    <!-- Joint to move the right aileron -->
    <joint name='right_aileron_joint' type='revolute'>
      <parent>body</parent>
      <child>right_aileron</child>
      <pose>-1.45 -3.7 1.5 -0.05 0 0.12</pose>
      <axis>
        <xyz>0 1 0</xyz>
        <limit>
          <!-- -30/+30 deg. -->
          <lower>-0.53</lower>
          <upper>0.53</upper>
          <effort>-1</effort>
          <velocity>-1</velocity>
        </limit>
        <dynamics>
          <damping>1.000</damping>
        </dynamics>
      </axis>
      <physics>
        <ode>
          <implicit_spring_damper>1</implicit_spring_damper>
        </ode>
      </physics>
    </joint>

    <!-- Joint to move the elevators -->
    <joint name='elevators_joint' type='revolute'>
      <parent>body</parent>
      <child>elevators</child>
      <pose>-5.55 0 0.57 0 0 0</pose>
      <axis>
        <xyz>0 1 0</xyz>
        <limit>
          <!-- -30/+30 deg. -->
          <lower>-0.53</lower>
          <upper>0.53</upper>
          <effort>-1</effort>
          <velocity>-1</velocity>
        </limit>
        <dynamics>
          <damping>1.000</damping>
        </dynamics>
      </axis>
      <physics>
        <ode>
          <implicit_spring_damper>1</implicit_spring_damper>
        </ode>
      </physics>
    </joint>

    <!-- Joint to move the rudder -->
    <joint name='rudder_joint' type='revolute'>
      <parent>body</parent>
      <child>rudder</child>
      <pose>-5.9 0 1.3 0 -0.35 0</pose>
      <axis>
        <xyz>0 0 1</xyz>
        <limit>
          <!-- -30/+30 deg. -->
          <lower>-0.53</lower>
          <upper>0.53</upper>
          <effort>-1</effort>
          <velocity>-1</velocity>
        </limit>
        <dynamics>
          <damping>1.000</damping>
        </dynamics>
      </axis>
      <physics>
        <ode>
          <implicit_spring_damper>1</implicit_spring_damper>
        </ode>
      </physics>
    </joint>

    <!-- Joint to make the propeller spin -->
    <joint name='propeller_joint' type='revolute'>
      <parent>body</parent>
      <child>propeller</child>
      <axis>
        <xyz>1 0 0</xyz>
        <limit>
          <lower>-1e+12</lower>
          <upper>1e+12</upper>
          <effort>-1</effort>
          <velocity>-1</velocity>
        </limit>
        <dynamics>
          <damping>0.001</damping>
        </dynamics>
      </axis>
      <physics>
        <ode>
          <implicit_spring_damper>1</implicit_spring_damper>
        </ode>
      </physics>
    </joint>

    <!-- Joint to make the front wheel spin -->
    <joint name='front_wheel_joint' type='revolute'>
      <parent>body</parent>
      <child>front_wheel</child>
      <pose>0.712 0 -0.313 0 0 0</pose>
      <axis>
        <xyz>0 1 0</xyz>
        <limit>
          <lower>-1e+12</lower>
          <upper>1e+12</upper>
          <effort>-1</effort>
          <velocity>-1</velocity>
        </limit>
        <dynamics>
          <damping>0.010</damping>
        </dynamics>
      </axis>
      <physics>
        <ode>
          <implicit_spring_damper>1</implicit_spring_damper>
        </ode>
      </physics>
    </joint>

    <!-- Joint to make the rear left wheel spin -->
    <joint name='rear_left_wheel_joint' type='revolute'>
      <parent>body</parent>
      <child>rear_left_wheel</child>
      <pose>-1 -1.27 -0.25 0 0 0</pose>
      <axis>
        <xyz>0 1 0</xyz>
        <limit>
          <lower>-1e+12</lower>
          <upper>1e+12</upper>
          <effort>-1</effort>
          <velocity>-1</velocity>
        </limit>
        <dynamics>
          <damping>0.010</damping>
        </dynamics>
      </axis>
      <physics>
        <ode>
          <implicit_spring_damper>1</implicit_spring_damper>
        </ode>
      </physics>
    </joint>

    <!-- Joint to make the rear right wheel spin -->
    <joint name='rear_right_wheel_joint' type='revolute'>
      <parent>body</parent>
      <child>rear_right_wheel</child>
      <pose>-1 1.27 -0.25 0 0 0</pose>
      <axis>
        <xyz>0 1 0</xyz>
        <limit>
          <lower>-1e+12</lower>
          <upper>1e+12</upper>
          <effort>-1</effort>
          <velocity>-1</velocity>
        </limit>
        <dynamics>
          <damping>0.010</damping>
        </dynamics>
      </axis>
      <physics>
        <ode>
          <implicit_spring_damper>1</implicit_spring_damper>
        </ode>
      </physics>
    </joint>

    <joint name="gps_joint" type="fixed">
      <parent>body</parent>
      <child>link_6</child>
      <pose frame=''>0 0 0 1.58268 0 0</pose>
    </joint>

    <joint name="gps_joints" type="fixed">
      <parent>body</parent>
      <child>link_6_clone</child>
      <pose>-0.7 0 1.5 -1.5708 0 3.1415</pose>
    </joint>

  </model>

</sdf>
